#VRML_SIM R2019a utf8
WorldInfo {
  info [
    "Example world demonstrating the use of the Muscle node"
  ]
  title "Muscle"
  basicTimeStep 16
}
Viewpoint {
  orientation 0.5466907678716743 0.7819788676126852 0.299396484500172 0.14608765135061086
  position 0.10278141282116625 -0.01423007653311855 0.25973123533387327
}
TexturedBackground {
}
TexturedBackgroundLight {
}
Floor {
  size 3 3
}
DEF HINGE Robot {
  translation 0 0.035 0
  children [
    DEF BOX Transform {
      translation -0.025 -0.01 0
      children [
        Shape {
          appearance PBRAppearance {
            baseColor 0.8 0.8 0.8
            roughness 1
            metalness 0
          }
          geometry Box {
            size 0.05 0.06 0.08
          }
        }
      ]
    }
    DEF JOINT Shape {
      appearance PBRAppearance {
        baseColor 0.337255 0.337255 0.337255
        transparency 0.009999999776482582
        roughness 1
        metalness 0
      }
      geometry Sphere {
        radius 0.008
      }
    }
    DEF BONE1 Transform {
      translation 0.05 1.6835523e-07 0
      rotation 0 0 1 1.5707997
      children [
        Shape {
          appearance PBRAppearance {
            baseColor 0.8 0.8 0.8
            roughness 1
            metalness 0
          }
          geometry Capsule {
            height 0.1
            radius 0.005
          }
        }
      ]
    }
    Transform {
      translation 0.08 -0.1 0
      children [
        Shape {
          appearance PBRAppearance {
            baseColor 0 0 1
            emissiveColor 0 0 1
          }
          geometry Sphere {
            radius 0.005
            subdivision 3
          }
        }
      ]
    }
    HingeJoint {
      jointParameters HingeJointParameters {
        axis 0 0 1
        anchor 0.1 0 0
        dampingConstant 0.4
      }
      device [
        RotationalMotor {
          name "muscle"
          controlPID 1 0.1 0
          minPosition -0.5
          maxPosition 3
          maxTorque 0.5
          muscles [
            Muscle {
              maxRadius 0.02
              startOffset 0.01 0 0
              endOffset 0 0.05 0
              center 0.08 -0.1 0
              color [
                1 0 0
                1 1 0
                1 0 1
              ]
              castShadows FALSE
            }
          ]
        }
        PositionSensor {
        }
      ]
      endPoint Solid {
        translation 0.1 0 0
        rotation 0 0 1 4.9078177
        children [
          USE JOINT
          DEF BONE2 Transform {
            translation 0 0.0225 0
            children [
              Shape {
                appearance PBRAppearance {
                  baseColor 0.8 0.8 0.8
                  roughness 1
                  metalness 0
                }
                geometry Capsule {
                  height 0.045
                  radius 0.005
                }
              }
            ]
          }
        ]
        boundingObject Group {
          children [
            USE JOINT
            USE BONE2
          ]
        }
        physics Physics {
          density -1
          mass 0.6
        }
      }
    }
  ]
  name "hinge"
  boundingObject Group {
    children [
      USE BOX
      USE JOINT
      USE BONE1
    ]
  }
  physics Physics {
    density -1
    mass 20
    centerOfMass [
      -0.03 -0.015 0
    ]
  }
  controller "muscle"
}
